2024-05-12 16:34:29,599 - INFO - initialize.py:56 - Database initialized successfully!
2024-05-12 18:07:26,749 - ERROR - initialize.py:64 - Error initializing database: 2003 (HY000): Can't connect to MySQL server on 'task-management-mysql:3306' (111)
2024-05-12 18:07:26,749 - INFO - initialize.py:67 - Retrying database initialization (1 of 3)
2024-05-12 18:07:26,750 - ERROR - initialize.py:68 - Stack Traceback: Traceback (most recent call last):
  File "/usr/local/lib/python3.9/site-packages/mysql/connector/connection_cext.py", line 236, in _open_connection
    self._cmysql.connect(**cnx_kwargs)
_mysql_connector.MySQLInterfaceError: Can't connect to MySQL server on 'task-management-mysql:3306' (111)

During handling of the above exception, another exception occurred:

Traceback (most recent call last):
  File "/app/initialize.py", line 22, in initialize_database
    connection = mysql.connector.connect(
  File "/usr/local/lib/python3.9/site-packages/mysql/connector/__init__.py", line 272, in connect
    return CMySQLConnection(*args, **kwargs)
  File "/usr/local/lib/python3.9/site-packages/mysql/connector/connection_cext.py", line 85, in __init__
    self.connect(**kwargs)
  File "/usr/local/lib/python3.9/site-packages/mysql/connector/abstracts.py", line 1014, in connect
    self._open_connection()
  File "/usr/local/lib/python3.9/site-packages/mysql/connector/connection_cext.py", line 241, in _open_connection
    raise errors.get_mysql_exception(msg=exc.msg, errno=exc.errno,
mysql.connector.errors.DatabaseError: 2003 (HY000): Can't connect to MySQL server on 'task-management-mysql:3306' (111)

2024-05-12 18:07:36,754 - ERROR - initialize.py:64 - Error initializing database: 2003 (HY000): Can't connect to MySQL server on 'task-management-mysql:3306' (111)
2024-05-12 18:07:36,754 - INFO - initialize.py:67 - Retrying database initialization (2 of 3)
2024-05-12 18:07:36,755 - ERROR - initialize.py:68 - Stack Traceback: Traceback (most recent call last):
  File "/usr/local/lib/python3.9/site-packages/mysql/connector/connection_cext.py", line 236, in _open_connection
    self._cmysql.connect(**cnx_kwargs)
_mysql_connector.MySQLInterfaceError: Can't connect to MySQL server on 'task-management-mysql:3306' (111)

During handling of the above exception, another exception occurred:

Traceback (most recent call last):
  File "/app/initialize.py", line 22, in initialize_database
    connection = mysql.connector.connect(
  File "/usr/local/lib/python3.9/site-packages/mysql/connector/__init__.py", line 272, in connect
    return CMySQLConnection(*args, **kwargs)
  File "/usr/local/lib/python3.9/site-packages/mysql/connector/connection_cext.py", line 85, in __init__
    self.connect(**kwargs)
  File "/usr/local/lib/python3.9/site-packages/mysql/connector/abstracts.py", line 1014, in connect
    self._open_connection()
  File "/usr/local/lib/python3.9/site-packages/mysql/connector/connection_cext.py", line 241, in _open_connection
    raise errors.get_mysql_exception(msg=exc.msg, errno=exc.errno,
mysql.connector.errors.DatabaseError: 2003 (HY000): Can't connect to MySQL server on 'task-management-mysql:3306' (111)

2024-05-12 18:07:46,817 - INFO - initialize.py:56 - Database initialized successfully!
2024-05-13 15:38:42,014 - ERROR - initialize.py:64 - Error initializing database: 2003 (HY000): Can't connect to MySQL server on 'task-management-mysql:3306' (111)
2024-05-13 15:38:42,014 - INFO - initialize.py:67 - Retrying database initialization (1 of 3)
2024-05-13 15:38:42,028 - ERROR - initialize.py:68 - Stack Traceback: Traceback (most recent call last):
  File "/usr/local/lib/python3.9/site-packages/mysql/connector/connection_cext.py", line 236, in _open_connection
    self._cmysql.connect(**cnx_kwargs)
_mysql_connector.MySQLInterfaceError: Can't connect to MySQL server on 'task-management-mysql:3306' (111)

During handling of the above exception, another exception occurred:

Traceback (most recent call last):
  File "/app/initialize.py", line 22, in initialize_database
    connection = mysql.connector.connect(
  File "/usr/local/lib/python3.9/site-packages/mysql/connector/__init__.py", line 272, in connect
    return CMySQLConnection(*args, **kwargs)
  File "/usr/local/lib/python3.9/site-packages/mysql/connector/connection_cext.py", line 85, in __init__
    self.connect(**kwargs)
  File "/usr/local/lib/python3.9/site-packages/mysql/connector/abstracts.py", line 1014, in connect
    self._open_connection()
  File "/usr/local/lib/python3.9/site-packages/mysql/connector/connection_cext.py", line 241, in _open_connection
    raise errors.get_mysql_exception(msg=exc.msg, errno=exc.errno,
mysql.connector.errors.DatabaseError: 2003 (HY000): Can't connect to MySQL server on 'task-management-mysql:3306' (111)

2024-05-13 15:38:52,395 - INFO - initialize.py:56 - Database initialized successfully!
2024-05-13 16:03:04,787 - ERROR - initialize.py:64 - Error initializing database: 2003 (HY000): Can't connect to MySQL server on 'task-management-mysql:3306' (111)
2024-05-13 16:03:04,817 - INFO - initialize.py:67 - Retrying database initialization (1 of 3)
2024-05-13 16:03:04,819 - ERROR - initialize.py:68 - Stack Traceback: Traceback (most recent call last):
  File "/usr/local/lib/python3.9/site-packages/mysql/connector/connection_cext.py", line 236, in _open_connection
    self._cmysql.connect(**cnx_kwargs)
_mysql_connector.MySQLInterfaceError: Can't connect to MySQL server on 'task-management-mysql:3306' (111)

During handling of the above exception, another exception occurred:

Traceback (most recent call last):
  File "/app/initialize.py", line 22, in initialize_database
    connection = mysql.connector.connect(
  File "/usr/local/lib/python3.9/site-packages/mysql/connector/__init__.py", line 272, in connect
    return CMySQLConnection(*args, **kwargs)
  File "/usr/local/lib/python3.9/site-packages/mysql/connector/connection_cext.py", line 85, in __init__
    self.connect(**kwargs)
  File "/usr/local/lib/python3.9/site-packages/mysql/connector/abstracts.py", line 1014, in connect
    self._open_connection()
  File "/usr/local/lib/python3.9/site-packages/mysql/connector/connection_cext.py", line 241, in _open_connection
    raise errors.get_mysql_exception(msg=exc.msg, errno=exc.errno,
mysql.connector.errors.DatabaseError: 2003 (HY000): Can't connect to MySQL server on 'task-management-mysql:3306' (111)

2024-05-13 16:03:14,837 - ERROR - initialize.py:64 - Error initializing database: 2003 (HY000): Can't connect to MySQL server on 'task-management-mysql:3306' (111)
2024-05-13 16:03:14,838 - INFO - initialize.py:67 - Retrying database initialization (2 of 3)
2024-05-13 16:03:14,838 - ERROR - initialize.py:68 - Stack Traceback: Traceback (most recent call last):
  File "/usr/local/lib/python3.9/site-packages/mysql/connector/connection_cext.py", line 236, in _open_connection
    self._cmysql.connect(**cnx_kwargs)
_mysql_connector.MySQLInterfaceError: Can't connect to MySQL server on 'task-management-mysql:3306' (111)

During handling of the above exception, another exception occurred:

Traceback (most recent call last):
  File "/app/initialize.py", line 22, in initialize_database
    connection = mysql.connector.connect(
  File "/usr/local/lib/python3.9/site-packages/mysql/connector/__init__.py", line 272, in connect
    return CMySQLConnection(*args, **kwargs)
  File "/usr/local/lib/python3.9/site-packages/mysql/connector/connection_cext.py", line 85, in __init__
    self.connect(**kwargs)
  File "/usr/local/lib/python3.9/site-packages/mysql/connector/abstracts.py", line 1014, in connect
    self._open_connection()
  File "/usr/local/lib/python3.9/site-packages/mysql/connector/connection_cext.py", line 241, in _open_connection
    raise errors.get_mysql_exception(msg=exc.msg, errno=exc.errno,
mysql.connector.errors.DatabaseError: 2003 (HY000): Can't connect to MySQL server on 'task-management-mysql:3306' (111)

2024-05-13 16:03:24,848 - ERROR - initialize.py:64 - Error initializing database: 2003 (HY000): Can't connect to MySQL server on 'task-management-mysql:3306' (111)
2024-05-13 16:03:24,849 - ERROR - initialize.py:71 - Failed to initialize database after multiple retries
2024-05-13 16:05:16,130 - INFO - initialize.py:56 - Database initialized successfully!
2024-05-13 16:15:46,910 - INFO - initialize.py:56 - Database initialized successfully!
2024-05-13 16:21:56,376 - INFO - initialize.py:56 - Database initialized successfully!
2024-05-13 18:27:59,000 - ERROR - initialize.py:64 - Error initializing database: 2003 (HY000): Can't connect to MySQL server on 'task-management-mysql:3306' (111)
2024-05-13 18:27:59,030 - INFO - initialize.py:67 - Retrying database initialization (1 of 3)
2024-05-13 18:27:59,033 - ERROR - initialize.py:68 - Stack Traceback: Traceback (most recent call last):
  File "/usr/local/lib/python3.9/site-packages/mysql/connector/connection_cext.py", line 236, in _open_connection
    self._cmysql.connect(**cnx_kwargs)
_mysql_connector.MySQLInterfaceError: Can't connect to MySQL server on 'task-management-mysql:3306' (111)

During handling of the above exception, another exception occurred:

Traceback (most recent call last):
  File "/app/initialize.py", line 22, in initialize_database
    connection = mysql.connector.connect(
  File "/usr/local/lib/python3.9/site-packages/mysql/connector/__init__.py", line 272, in connect
    return CMySQLConnection(*args, **kwargs)
  File "/usr/local/lib/python3.9/site-packages/mysql/connector/connection_cext.py", line 85, in __init__
    self.connect(**kwargs)
  File "/usr/local/lib/python3.9/site-packages/mysql/connector/abstracts.py", line 1014, in connect
    self._open_connection()
  File "/usr/local/lib/python3.9/site-packages/mysql/connector/connection_cext.py", line 241, in _open_connection
    raise errors.get_mysql_exception(msg=exc.msg, errno=exc.errno,
mysql.connector.errors.DatabaseError: 2003 (HY000): Can't connect to MySQL server on 'task-management-mysql:3306' (111)

2024-05-13 18:28:09,085 - INFO - initialize.py:56 - Database initialized successfully!
2024-05-13 19:29:01,334 - ERROR - initialize.py:64 - Error initializing database: 2003 (HY000): Can't connect to MySQL server on 'task-management-mysql:3306' (111)
2024-05-13 19:29:01,334 - INFO - initialize.py:67 - Retrying database initialization (1 of 3)
2024-05-13 19:29:11,390 - INFO - initialize.py:56 - Database initialized successfully!
2024-05-13 20:27:56,589 - INFO - initialize.py:56 - Database initialized successfully!
2024-05-13 20:29:54,817 - INFO - initialize.py:56 - Database initialized successfully!
